import asyncio
import traceback
import logging
import discord
from discord.ext import commands
from discord.ext.commands import errors
from app.state import AppState


log = logging.getLogger(__name__)
TEST_GUILD_ID = 808797581547012146

ACK_REACTION = "ðŸ†—"
ACK_TIME_S = 4


class BaseCog(commands.Cog):
    def __init__(self, state: AppState, bot: discord.ext.commands.bot.Bot, **other):
        self.state = state
        self.bot = bot
        super().__init__()
        self.__handled_error_message_ids = set()

    def is_bot(self, id: int):
        return id == self.bot.user.id

    async def ack(self, message: discord.Message, keep=False):
        asyncio.create_task(self.__ack(message, keep))

    async def __ack(self, message: discord.Message, keep=False):
        await message.add_reaction(ACK_REACTION)
        if not keep:
            await asyncio.sleep(ACK_TIME_S)
            await message.remove_reaction(ACK_REACTION, self.bot.user)

    @staticmethod
    async def error(channel: discord.TextChannel, response_text: str):
        sent = await channel.send(response_text)
        return sent

    @commands.Cog.listener()
    async def on_command_error(self, error, ctx):
        pass
        # self.bot.help_command()

    @commands.Cog.listener()
    async def on_command_error(self, ctx, error):
        """The event triggered when an error is raised while invoking a command.
        Parameters
        ------------
        ctx: commands.Context
            The context used for command invocation.
        error: commands.CommandError
            The Exception raised.
        """

        if ctx.guild.id == TEST_GUILD_ID:
            traceback.print_exception(type(error), error, error.__traceback__)
        else:
            log.error(str(error))
